Workbook

Sheet SİPARİŞ FORMU
B1: SİPARİŞ BİLGİLERİ
B2: SIRA NO | C2: MÜŞTERİ KODU | D2: MÜŞTERİ ADI | E2: KALİTE GRUP | F2: DALGA | G2: KALİTE | H2: RİL TİPİ | I2: RİL 1 | J2: RİL 2 | K2: RİL 3 | L2: RİL 4 | M2: RİL 5 | N2: RİL 6 | O2: RİL 7 | P2: RİL 8 | Q2: LEVHA EN RİLSİZ (mm) | R2: LEVHA EN (mm) | S2: LEVHA BOY (mm) | T2: SİPARİŞ TÜRÜ | U2: SEVK YERİ | V2: VADE | W2: TALEP EDİLEN TESLİM TARİHİ | X2: SİPARİŞ ADET | Y2: FİYAT | Z2: BİRİM | AA2: FSC | AB2: REFERANS SİPARİŞ NO | AC2: MÜŞTERİ MALZEME NO
B3: 1. | F3: EB | G3: BTL-HPFL-KM,110/115/80/115/100 | H3: RİLSİZ | Q3: 884 | R3: =IF(H3="","",IF(OR(H3<>"RİLSİZ",H3=" "),IF(AND(SUM(I3:P3)>='ANA VERİLER'!$C$81,SUM(I3:P3)<='ANA VERİLER'!$C$82),SUM(I3:P3),"Levha eni minimum 300 mm - maksimum 2.500 mm olmalıdır!"),Q3)) -> 884 | S3: 926 | T3: =+IF(E3<>"","STANDART SİPARİŞ","") | U3: ADANA | X3: 2500 | Y3: =+IFERROR(IF(E3="LİSTE",VLOOKUP(F3&" "&G3,'ANA VERİLER'!$E$16:$H$52,4,0)," ")," ") | Z3: =+IFERROR(VLOOKUP(F3&" "&G3,'ANA VERİLER'!$E$16:$I$52,5,0)," ")
B4: 2. | R4: =IF(H4="","",IF(OR(H4<>"RİLSİZ",H4=" "),IF(AND(SUM(I4:P4)>='ANA VERİLER'!$C$81,SUM(I4:P4)<='ANA VERİLER'!$C$82),SUM(I4:P4),"Levha eni minimum 300 mm - maksimum 2.500 mm olmalıdır!"),Q4)) | T4: =+IF(E4<>"","STANDART SİPARİŞ","") | Y4: =+IFERROR(IF(E4="LİSTE",VLOOKUP(F4&" "&G4,'ANA VERİLER'!$E$16:$H$52,4,0)," ")," ") | Z4: =+IFERROR(VLOOKUP(F4&" "&G4,'ANA VERİLER'!$E$16:$I$52,5,0)," ")
B5: 3. | R5: =IF(H5="","",IF(OR(H5<>"RİLSİZ",H5=" "),IF(AND(SUM(I5:P5)>='ANA VERİLER'!$C$81,SUM(I5:P5)<='ANA VERİLER'!$C$82),SUM(I5:P5),"Levha eni minimum 300 mm - maksimum 2.500 mm olmalıdır!"),Q5)) | T5: =+IF(E5<>"","STANDART SİPARİŞ","") | Y5: =+IFERROR(IF(E5="LİSTE",VLOOKUP(F5&" "&G5,'ANA VERİLER'!$E$16:$H$52,4,0)," ")," ") | Z5: =+IFERROR(VLOOKUP(F5&" "&G5,'ANA VERİLER'!$E$16:$I$52,5,0)," ")
B6: 4. | R6: =IF(H6="","",IF(OR(H6<>"RİLSİZ",H6=" "),IF(AND(SUM(I6:P6)>='ANA VERİLER'!$C$81,SUM(I6:P6)<='ANA VERİLER'!$C$82),SUM(I6:P6),"Levha eni minimum 300 mm - maksimum 2.500 mm olmalıdır!"),Q6)) | T6: =+IF(E6<>"","STANDART SİPARİŞ","") | Y6: =+IFERROR(IF(E6="LİSTE",VLOOKUP(F6&" "&G6,'ANA VERİLER'!$E$16:$H$52,4,0)," ")," ") | Z6: =+IFERROR(VLOOKUP(F6&" "&G6,'ANA VERİLER'!$E$16:$I$52,5,0)," ")
B7: 5. | R7: =IF(H7="","",IF(OR(H7<>"RİLSİZ",H7=" "),IF(AND(SUM(I7:P7)>='ANA VERİLER'!$C$81,SUM(I7:P7)<='ANA VERİLER'!$C$82),SUM(I7:P7),"Levha eni minimum 300 mm - maksimum 2.500 mm olmalıdır!"),Q7)) | T7: =+IF(E7<>"","STANDART SİPARİŞ","") | Y7: =+IFERROR(IF(E7="LİSTE",VLOOKUP(F7&" "&G7,'ANA VERİLER'!$E$16:$H$52,4,0)," ")," ") | Z7: =+IFERROR(VLOOKUP(F7&" "&G7,'ANA VERİLER'!$E$16:$I$52,5,0)," ")
B8: 6. | R8: =IF(H8="","",IF(OR(H8<>"RİLSİZ",H8=" "),IF(AND(SUM(I8:P8)>='ANA VERİLER'!$C$81,SUM(I8:P8)<='ANA VERİLER'!$C$82),SUM(I8:P8),"Levha eni minimum 300 mm - maksimum 2.500 mm olmalıdır!"),Q8)) | T8: =+IF(E8<>"","STANDART SİPARİŞ","") | Y8: =+IFERROR(IF(E8="LİSTE",VLOOKUP(F8&" "&G8,'ANA VERİLER'!$E$16:$H$52,4,0)," ")," ") | Z8: =+IFERROR(VLOOKUP(F8&" "&G8,'ANA VERİLER'!$E$16:$I$52,5,0)," ")
B9: 7. | R9: =IF(H9="","",IF(OR(H9<>"RİLSİZ",H9=" "),IF(AND(SUM(I9:P9)>='ANA VERİLER'!$C$81,SUM(I9:P9)<='ANA VERİLER'!$C$82),SUM(I9:P9),"Levha eni minimum 300 mm - maksimum 2.500 mm olmalıdır!"),Q9)) | T9: =+IF(E9<>"","STANDART SİPARİŞ","") | Y9: =+IFERROR(IF(E9="LİSTE",VLOOKUP(F9&" "&G9,'ANA VERİLER'!$E$16:$H$52,4,0)," ")," ") | Z9: =+IFERROR(VLOOKUP(F9&" "&G9,'ANA VERİLER'!$E$16:$I$52,5,0)," ")
B10: 8. | R10: =IF(H10="","",IF(OR(H10<>"RİLSİZ",H10=" "),IF(AND(SUM(I10:P10)>='ANA VERİLER'!$C$81,SUM(I10:P10)<='ANA VERİLER'!$C$82),SUM(I10:P10),"Levha eni minimum 300 mm - maksimum 2.500 mm olmalıdır!"),Q10)) | T10: =+IF(E10<>"","STANDART SİPARİŞ","") | Y10: =+IFERROR(IF(E10="LİSTE",VLOOKUP(F10&" "&G10,'ANA VERİLER'!$E$16:$H$52,4,0)," ")," ") | Z10: =+IFERROR(VLOOKUP(F10&" "&G10,'ANA VERİLER'!$E$16:$I$52,5,0)," ")
B11: 9. | R11: =IF(H11="","",IF(OR(H11<>"RİLSİZ",H11=" "),IF(AND(SUM(I11:P11)>='ANA VERİLER'!$C$81,SUM(I11:P11)<='ANA VERİLER'!$C$82),SUM(I11:P11),"Levha eni minimum 300 mm - maksimum 2.500 mm olmalıdır!"),Q11)) | T11: =+IF(E11<>"","STANDART SİPARİŞ","") | Y11: =+IFERROR(IF(E11="LİSTE",VLOOKUP(F11&" "&G11,'ANA VERİLER'!$E$16:$H$52,4,0)," ")," ") | Z11: =+IFERROR(VLOOKUP(F11&" "&G11,'ANA VERİLER'!$E$16:$I$52,5,0)," ")
B12: 10. | R12: =IF(H12="","",IF(OR(H12<>"RİLSİZ",H12=" "),IF(AND(SUM(I12:P12)>='ANA VERİLER'!$C$81,SUM(I12:P12)<='ANA VERİLER'!$C$82),SUM(I12:P12),"Levha eni minimum 300 mm - maksimum 2.500 mm olmalıdır!"),Q12)) | T12: =+IF(E12<>"","STANDART SİPARİŞ","") | Y12: =+IFERROR(IF(E12="LİSTE",VLOOKUP(F12&" "&G12,'ANA VERİLER'!$E$16:$H$52,4,0)," ")," ") | Z12: =+IFERROR(VLOOKUP(F12&" "&G12,'ANA VERİLER'!$E$16:$I$52,5,0)," ")
B13: 11. | R13: =IF(H13="","",IF(OR(H13<>"RİLSİZ",H13=" "),IF(AND(SUM(I13:P13)>='ANA VERİLER'!$C$81,SUM(I13:P13)<='ANA VERİLER'!$C$82),SUM(I13:P13),"Levha eni minimum 300 mm - maksimum 2.500 mm olmalıdır!"),Q13)) | T13: =+IF(E13<>"","STANDART SİPARİŞ","") | Y13: =+IFERROR(IF(E13="LİSTE",VLOOKUP(F13&" "&G13,'ANA VERİLER'!$E$16:$H$52,4,0)," ")," ") | Z13: =+IFERROR(VLOOKUP(F13&" "&G13,'ANA VERİLER'!$E$16:$I$52,5,0)," ")
B14: 12. | R14: =IF(H14="","",IF(OR(H14<>"RİLSİZ",H14=" "),IF(AND(SUM(I14:P14)>='ANA VERİLER'!$C$81,SUM(I14:P14)<='ANA VERİLER'!$C$82),SUM(I14:P14),"Levha eni minimum 300 mm - maksimum 2.500 mm olmalıdır!"),Q14)) | T14: =+IF(E14<>"","STANDART SİPARİŞ","") | Y14: =+IFERROR(IF(E14="LİSTE",VLOOKUP(F14&" "&G14,'ANA VERİLER'!$E$16:$H$52,4,0)," ")," ") | Z14: =+IFERROR(VLOOKUP(F14&" "&G14,'ANA VERİLER'!$E$16:$I$52,5,0)," ")
B15: 13. | R15: =IF(H15="","",IF(OR(H15<>"RİLSİZ",H15=" "),IF(AND(SUM(I15:P15)>='ANA VERİLER'!$C$81,SUM(I15:P15)<='ANA VERİLER'!$C$82),SUM(I15:P15),"Levha eni minimum 300 mm - maksimum 2.500 mm olmalıdır!"),Q15)) | T15: =+IF(E15<>"","STANDART SİPARİŞ","") | Y15: =+IFERROR(IF(E15="LİSTE",VLOOKUP(F15&" "&G15,'ANA VERİLER'!$E$16:$H$52,4,0)," ")," ") | Z15: =+IFERROR(VLOOKUP(F15&" "&G15,'ANA VERİLER'!$E$16:$I$52,5,0)," ")
... B52: 50. | R52: =IF(H52="","",IF(OR(H52<>"RİLSİZ",H52=" "),IF(AND(SUM(I52:P52)>='ANA VERİLER'!$C$81,SUM(I52:P52)<='ANA VERİLER'!$C$82),SUM(I52:P52),"Levha eni minimum 300 mm - maksimum 2.500 mm olmalıdır!"),Q52)) | T52: =+IF(E52<>"","STANDART SİPARİŞ","") | Y52: =+IFERROR(IF(E52="LİSTE",VLOOKUP(F52&" "&G52,'ANA VERİLER'!$E$16:$H$52,4,0)," ")," ") | Z52: =+IFERROR(VLOOKUP(F52&" "&G52,'ANA VERİLER'!$E$16:$I$52,5,0)," ")

Sheet ANA VERİLER
B1: ANA VERİLER
B3: ÜRETİM YERLERİ
B4: ÜRETİM YERİ | C4: ÜRÜN KARTI TÜRÜ
B5: 1002 | C5: LVH
B8: MAL GRUPLARI
B9: MAL GRUBU | C9: TANIM | D9: AÇIKLAMA
B10: 2000101 | C10: PLAKA - DÜZ PLAKA | D10: Aşağıdaki koşulların dışındaki tüm durumlar
B11: 2000103 | C11: PLAKA - SIRTI AÇIK | D11: EB, BC dagalarda 4 kağıt varsa
D12: E, B, C dalgalarda 2 kağıt varsa
F13: STD | G13: GRM
E14: İskonto Oran
B15: İSKONTO ORANLARI
B16: KALİTE GRUP | C16: DALGA | D16: KALİTE | E16: TAM KALİTE | F16: LİSTE FİYAT | G16: MÜŞTERİ İSKONTO ORAN | H16: İSKONTOLU FİYAT | I16: PARA BİRİMİ | J16: STD/GRM
B17: LİSTE | C17: E | D17: TL80 HPFL80 TL80 | E17: =+C17&" "&D17 -> E TL80 HPFL80 TL80 | F17: 12.97 | G17: =IF(J17="STD",$F$14,$G$14) -> 0 | H17: =ROUNDUP(F17*(1-G17),2) -> 12.97 | I17: TRY | J17: STD
B18: LİSTE | C18: E | D18: BTL110 HPFL80 TL80 | E18: =+C18&" "&D18 -> E BTL110 HPFL80 TL80 | F18: 15.3 | G18: =IF(J18="STD",$F$14,$G$14) -> 0 | H18: =ROUNDUP(F18*(1-G18),2) -> 15.3 | I18: TRY | J18: STD
B19: LİSTE | C19: E | D19: KM100 HPFL100 KM100 | E19: =+C19&" "&D19 -> E KM100 HPFL100 KM100 | F19: 14.96 | G19: =IF(J19="STD",$F$14,$G$14) -> 0 | H19: =ROUNDUP(F19*(1-G19),2) -> 14.96 | I19: TRY | J19: GRM
B20: LİSTE | C20: E | D20: KM100 HPFL135 KM100 | E20: =+C20&" "&D20 -> E KM100 HPFL135 KM100 | F20: 16.76 | G20: =IF(J20="STD",$F$14,$G$14) -> 0 | H20: =ROUNDUP(F20*(1-G20),2) -> 16.76 | I20: TRY | J20: GRM
B21: LİSTE | C21: B | D21: TL80 HPFL80 TL80 | E21: =+C21&" "&D21 -> B TL80 HPFL80 TL80 | F21: 12.66 | G21: =IF(J21="STD",$F$14,$G$14) -> 0 | H21: =ROUNDUP(F21*(1-G21),2) -> 12.66 | I21: TRY | J21: STD
B22: LİSTE | C22: B | D22: BTL110 HPFL80 TL80 | E22: =+C22&" "&D22 -> B BTL110 HPFL80 TL80 | F22: 14.88 | G22: =IF(J22="STD",$F$14,$G$14) -> 0 | H22: =ROUNDUP(F22*(1-G22),2) -> 14.88 | I22: TRY | J22: STD
B23: LİSTE | C23: B | D23: KM100 HPFL100 KM100 | E23: =+C23&" "&D23 -> B KM100 HPFL100 KM100 | F23: 14.91 | G23: =IF(J23="STD",$F$14,$G$14) -> 0 | H23: =ROUNDUP(F23*(1-G23),2) -> 14.91 | I23: TRY | J23: GRM
B24: LİSTE | C24: B | D24: KM100 HPFL135 KM100 | E24: =+C24&" "&D24 -> B KM100 HPFL135 KM100 | F24: 16.77 | G24: =IF(J24="STD",$F$14,$G$14) -> 0 | H24: =ROUNDUP(F24*(1-G24),2) -> 16.77 | I24: TRY | J24: GRM
B25: LİSTE | C25: B | D25: BTL110 HPFL115 KM100 | E25: =+C25&" "&D25 -> B BTL110 HPFL115 KM100 | F25: 18.17 | G25: =IF(J25="STD",$F$14,$G$14) -> 0 | H25: =ROUNDUP(F25*(1-G25),2) -> 18.17 | I25: TRY | J25: GRM
B26: LİSTE | C26: C | D26: TL80 HPFL80 TL80 | E26: =+C26&" "&D26 -> C TL80 HPFL80 TL80 | F26: 13.03 | G26: =IF(J26="STD",$F$14,$G$14) -> 0 | H26: =ROUNDUP(F26*(1-G26),2) -> 13.03 | I26: TRY | J26: STD
B27: LİSTE | C27: C | D27: BTL110 HPFL80 TL80 | E27: =+C27&" "&D27 -> C BTL110 HPFL80 TL80 | F27: 15.27 | G27: =IF(J27="STD",$F$14,$G$14) -> 0 | H27: =ROUNDUP(F27*(1-G27),2) -> 15.27 | I27: TRY | J27: STD
B28: LİSTE | C28: C | D28: KM100 HPFL100 KM100 | E28: =+C28&" "&D28 -> C KM100 HPFL100 KM100 | F28: 15.34 | G28: =IF(J28="STD",$F$14,$G$14) -> 0 | H28: =ROUNDUP(F28*(1-G28),2) -> 15.34 | I28: TRY | J28: GRM
... B52: LİSTE | C52: BC | D52: BTL110 HPFL135 HPFL80 HPFL135 KM135 | E52: =+C52&" "&D52 -> BC BTL110 HPFL135 HPFL80 HPFL135 KM135 | F52: 30.94 | G52: =IF(J52="STD",$F$14,$G$14) -> 0 | H52: =ROUNDUP(F52*(1-G52),2) -> 30.94 | I52: TRY | J52: GRM
B54: DALGA BİLGİLERİ
B55: KALİTE GRUP | C55: DALGA
B56: LİSTE | C56: E
B57: LİSTE | C57: B
B58: LİSTE | C58: C
B59: LİSTE | C59: EB
B60: LİSTE | C60: BC
B62: KALİTE GRUPLARI
B63: KALİTE GRUP
B64: LİSTE
B65: ÖZEL
B67: ALTERNATİF BOBİN ENLERİ
B68: ÖNCELİK SIRASI | C68: ALTERNATİF BOBİN ENİ
B69: 1 | C69: 2500
...

Sheet GEÇERLİLİK
B1: GEÇERLİLİK VERİLERİ
B2: Başlangıç Tarihi | C2: Bitiş Tarihi | D2: Referans No
B3: 01.05.2026 | C3: 31.05.2026
